<?xml version="1.0" ?>

<robot name="mobile_printer" xmlns:xacro="http://www.ros.org/wiki/xacro">
  
  <gazebo reference="base_link">
    <mu1>0.2</mu1>
    <mu2>0.2</mu2>
    <dampingFactor>0.2</dampingFactor>
    <material>Gazebo/Orange</material>
    <selfCollide>true</selfCollide>
  </gazebo>
  
  <gazebo reference="shoulder_link">
    <mu1>0.2</mu1>
    <mu2>0.2</mu2>
    <dampingFactor>0.2</dampingFactor>
    <material>Gazebo/Red</material>
    <selfCollide>true</selfCollide>
  </gazebo>

  <gazebo reference="prism_link">
    <mu1>0.2</mu1>
    <mu2>0.2</mu2>
    <dampingFactor>0.2</dampingFactor>
    <material>Gazebo/Orange</material>
    <selfCollide>true</selfCollide>
  </gazebo>
  
  <gazebo reference="elbow_link">
    <mu1>0.2</mu1>
    <mu2>0.2</mu2>
    <dampingFactor>0.2</dampingFactor>
    <material>Gazebo/Blue</material>
    <selfCollide>true</selfCollide>
  </gazebo>

  <gazebo reference="swerve_left_front_link">
    <mu1>0.2</mu1>
    <mu2>0.2</mu2>
    <material>Gazebo/Blue</material>
    <selfCollide>true</selfCollide>
    <dampingFactor>0.2</dampingFactor>
  </gazebo>

  <gazebo reference="swerve_right_front_link">
    <mu1>0.2</mu1>
    <mu2>0.2</mu2>
    <material>Gazebo/Blue</material>
    <selfCollide>true</selfCollide>
    <dampingFactor>0.2</dampingFactor>
  </gazebo>

  <gazebo reference="swerve_left_back_link">
    <mu1>0.2</mu1>
    <mu2>0.2</mu2>
    <material>Gazebo/Blue</material>
    <selfCollide>true</selfCollide>
    <dampingFactor>0.2</dampingFactor>
  </gazebo>

  <gazebo reference="swerve_right_back_link">
    <mu1>0.2</mu1>
    <mu2>0.2</mu2>
    <material>Gazebo/Blue</material>
    <selfCollide>true</selfCollide>
    <dampingFactor>0.2</dampingFactor>
  </gazebo>

  <gazebo reference="left_front_wheel">
    <mu1>100000.0</mu1>
    <mu2>100000.0</mu2>
    <material>Gazebo/Blue</material>
    <selfCollide>true</selfCollide>
  </gazebo>

  <gazebo reference="right_front_wheel">
    <mu1>100000.0</mu1>
    <mu2>100000.0</mu2>
    <material>Gazebo/Blue</material>
    <selfCollide>true</selfCollide>
  </gazebo>

  <gazebo reference="left_back_wheel">
    <mu1>100000.0</mu1>
    <mu2>100000.0</mu2>
    <material>Gazebo/Blue</material>
    <selfCollide>true</selfCollide>
  </gazebo>

  <gazebo reference="right_back_wheel">
    <mu1>100000.0</mu1>
    <mu2>100000.0</mu2>
    <material>Gazebo/Blue</material>
    <selfCollide>true</selfCollide>
  </gazebo>

  <gazebo>
  <plugin name="gazebo_ros_control" filename="libgazebo_ros_control.so">
    <robotNamespace>/MYROBOT</robotNamespace>
    <robotSimType>gazebo_ros_control/DefaultRobotHWSim</robotSimType>
  </plugin>
</gazebo>

  <!-- Import Rviz colors -->
  <material name="black">
    <color rgba="0.0 0.0 0.0 1.0"/>
  </material>
  <material name="blue">
    <color rgba="0.0 0.0 0.8 1.0"/>
  </material>
  <material name="green">
    <color rgba="0.0 0.8 0.0 1.0"/>
  </material>
  <material name="grey">
    <color rgba="0.2 0.2 0.2 1.0"/>
  </material>
  <material name="orange">
    <color rgba="1.0 0.423529411765 0.0392156862745 1.0"/>
  </material>
  <material name="brown">
    <color rgba="0.870588235294 0.811764705882 0.764705882353 1.0"/>
  </material>
  <material name="red">
    <color rgba="0.8 0.0 0.0 1.0"/>
  </material>
  <material name="white">
    <color rgba="1.0 1.0 1.0 1.0"/>
  </material>
  
<link name="base_link">
    <inertial>
      <origin
        xyz="0 0 0.348"
        rpy="0 0 0" />
      <mass
        value="50" />
      <inertia
        ixx="5.60770884492841"
        ixy="0"
        ixz="0"
        iyy="1"
        iyz="-13.6550522201205"
        izz="1" />
    </inertial>
    <visual>
      <origin
        xyz="0 0 0.348"
        rpy="0 0 0" />
      <geometry>
        <mesh
          filename="package://printer_description/meshes/MPO_700_body_simple.SLDPRT.STL" />
      </geometry>
      <material
        name="">
        <color
          rgba="0.86667 0.9098 1 1" />
      </material>
    </visual>
    <collision>
      <origin
        xyz="0 0 0.348"
        rpy="0 0 0" />
      <geometry>
        <mesh
          filename="package://printer_description/meshes/MPO_700_body_simple.SLDPRT.STL" />
      </geometry>
    </collision>
  </link>

  <link
    name="shoulder_link">
    <inertial>
      <origin
        xyz="0 0 0"
        rpy="0 0 0" />
      <mass
        value="20" />
      <inertia
        ixx="11.663244910873"
        ixy="0"
        ixz="-0.463117260190688"
        iyy="1"
        iyz="-0.325943705018541"
        izz="1" />
    </inertial>
    <visual>
      <origin
        xyz="0 0 0"
        rpy="0 0 0" />
      <geometry>
        <mesh
          filename="package://printer_description/meshes/Arm_link1_simple.SLDPRT.STL" />
      </geometry>
      <material
        name="">
        <color
          rgba="0.86667 0.9098 1 1" />
      </material>
    </visual>
    <collision>
      <origin
        xyz="0 0 0"
        rpy="0 0 0" />
      <geometry>
        <mesh
          filename="package://printer_description/meshes/Arm_link1_simple.SLDPRT.STL" />
      </geometry>
    </collision>
  </link>

  <link
    name="prism_link">
    <inertial>
      <origin
        xyz="0 0 0"
        rpy="0 0 0" />
      <mass
        value="10" />
      <inertia
        ixx="1.9616662001775"
        ixy="-0.0491005071338084"
        ixz="0.00131624037987076"
        iyy="0.105829672288633"
        iyz="-1.9566286660684"
        izz="-0.105829672288633" />
    </inertial>
    <visual>
      <origin
        xyz="0 0 0"
        rpy="0 0 0" />
      <geometry>
        <mesh
          filename="package://printer_description/meshes/Arm_link2_simple.SLDPRT.STL" />
      </geometry>
      <material
        name="">
        <color
          rgba="0.86667 0.9098 1 1" />
      </material>
    </visual>
    <collision>
      <origin
        xyz="0 0 0"
        rpy="0 0 0" />
      <geometry>
        <mesh
          filename="package://printer_description/meshes/Arm_link2_simple.SLDPRT.STL" />
      </geometry>
    </collision>
  </link>

  <link
    name="elbow_link">
    <inertial>
      <origin
        xyz="0 0 0"
        rpy="0 0 0" />
      <mass
        value="10" />
      <inertia
        ixx="1.14535612773492"
        ixy="0"
        ixz="-0.625467963004431"
        iyy="1"
        iyz="-1.14069726824125"
        izz="1" />
    </inertial>
    <visual>
      <origin
        xyz="0 0 0"
        rpy="0 0 0" />
      <geometry>
        <mesh
          filename="package://printer_description/meshes/Arm_link3_simple.SLDPRT.STL" />
      </geometry>
      <material
        name="">
        <color
          rgba="0.86667 0.9098 1 1" />
      </material>
    </visual>
    <collision>
      <origin
        xyz="0 0 0"
        rpy="0 0 0" />
      <geometry>
        <mesh
          filename="package://printer_description/meshes/Arm_link3_simple.SLDPRT.STL" />
      </geometry>
    </collision>
  </link>

  <link name="swerve_left_front_link">
    <inertial>
      <origin
        xyz="0 0 0"
        rpy="0 0 0" />
      <mass
        value="10" />
      <inertia
        ixx="10"
        ixy="0"
        ixz="0"
        iyy="10"
        iyz="0"
        izz="10" />
    </inertial>
  </link>

  <link name="swerve_right_front_link">
    <inertial>
      <origin
        xyz="0 0 0"
        rpy="0 0 0" />
      <mass
        value="10" />
      <inertia
        ixx="10"
        ixy="0"
        ixz="0"
        iyy="10"
        iyz="0"
        izz="10" />
    </inertial>
  </link>

  <link name="swerve_left_back_link">
    <inertial>
      <origin
        xyz="0 0 0"
        rpy="0 0 0" />
      <mass
        value="10" />
      <inertia
        ixx="10"
        ixy="0"
        ixz="0"
        iyy="10"
        iyz="0"
        izz="10" />
    </inertial>
  </link>

  <link name="swerve_right_back_link">
    <inertial>
      <origin
        xyz="0 0 0"
        rpy="0 0 0" />
      <mass
        value="10" />
      <inertia
        ixx="10"
        ixy="0"
        ixz="0"
        iyy="10"
        iyz="0"
        izz="10" />
    </inertial>
  </link>

  <link
    name="left_front_wheel">
    <inertial>
      <origin
        xyz="0 0 0"
        rpy="0 0 0" />
      <mass
        value="10" />
      <inertia
        ixx="10"
        ixy="0"
        ixz="0"
        iyy="10"
        iyz="0"
        izz="10" />
    </inertial>
    <visual>
      <origin
        xyz="0 0 0"
        rpy="0 0 0" />
      <geometry>
        <mesh
          filename="package://printer_description/meshes/MPO_700_wheel_simple.SLDPRT.STL" />
      </geometry>
      <material
        name="">
        <color
          rgba="0.86667 0.9098 1 1" />
      </material>
    </visual>
    <collision>
      <origin
        xyz="0 0 0"
        rpy="0 0 0" />
      <geometry>
        <mesh
          filename="package://printer_description/meshes/MPO_700_wheel_simple.SLDPRT.STL" />
      </geometry>
    </collision>
  </link>

  <link
    name="right_front_wheel">
    <inertial>
      <origin
        xyz="0 0 0"
        rpy="0 0 0" />
      <mass
        value="10" />
      <inertia
        ixx="10"
        ixy="0"
        ixz="0"
        iyy="10"
        iyz="0"
        izz="10" />
    </inertial>
    <visual>
      <origin
        xyz="0 0 0"
        rpy="0 0 0" />
      <geometry>
        <mesh
          filename="package://printer_description/meshes/MPO_700_wheel_simple.SLDPRT.STL" />
      </geometry>
      <material
        name="">
        <color
          rgba="0.86667 0.9098 1 1" />
      </material>
    </visual>
    <collision>
      <origin
        xyz="0 0 0"
        rpy="0 0 0" />
      <geometry>
        <mesh
          filename="package://printer_description/meshes/MPO_700_wheel_simple.SLDPRT.STL" />
      </geometry>
    </collision>
  </link>

  <link
    name="left_back_wheel">
    <inertial>
      <origin
        xyz="0 0 0"
        rpy="0 0 0" />
      <mass
        value="10" />
      <inertia
        ixx="10"
        ixy="0"
        ixz="0"
        iyy="10"
        iyz="0"
        izz="10" />
    </inertial>
    <visual>
      <origin
        xyz="0 0 0"
        rpy="0 0 0" />
      <geometry>
        <mesh
          filename="package://printer_description/meshes/MPO_700_wheel_simple.SLDPRT.STL" />
      </geometry>
      <material
        name="">
        <color
          rgba="0.86667 0.9098 1 1" />
      </material>
    </visual>
    <collision>
      <origin
        xyz="0 0 0"
        rpy="0 0 0" />
      <geometry>
        <mesh
          filename="package://printer_description/meshes/MPO_700_wheel_simple.SLDPRT.STL" />
      </geometry>
    </collision>
  </link>

  <link
    name="right_back_wheel">
    <inertial>
      <origin
        xyz="0 0 0"
        rpy="0 0 0" />
      <mass
        value="10" />
      <inertia
        ixx="10"
        ixy="0"
        ixz="0"
        iyy="10"
        iyz="0"
        izz="10" />
    </inertial>
    <visual>
      <origin
        xyz="0 0 0"
        rpy="0 0 0" />
      <geometry>
        <mesh
          filename="package://printer_description/meshes/MPO_700_wheel_simple.SLDPRT.STL" />
      </geometry>
      <material
        name="">
        <color
          rgba="0.86667 0.9098 1 1" />
      </material>
    </visual>
    <collision>
      <origin
        xyz="0 0 0"
        rpy="0 0 0" />
      <geometry>
        <mesh
          filename="package://printer_description/meshes/MPO_700_wheel_simple.SLDPRT.STL" />
      </geometry>
    </collision>
  </link>

   <joint name="shoulder_joint" type="continuous">
    <parent link="base_link"/>
    <child link="shoulder_link"/>
    <origin rpy="0 0 0" xyz="0 0 0.348"/>
    <axis xyz="0 0 1"/>
  </joint>

<joint name="prism_joint" type="prismatic">
    <parent link="shoulder_link"/>
    <child link="prism_link"/>
    <origin rpy="0 0 0" xyz="0.0 0 .2"/>
    <axis xyz="0 0 1"/>
    <limit effort="1000.0" lower="0.0" upper="1" velocity="0.5"/>
  </joint>

  <joint name="elbow_joint" type="continuous">
    <parent link="prism_link"/>
    <child link="elbow_link"/>
    <origin rpy="0 0 0" xyz="0.03 0.51 0.1"/>
    <axis xyz="0 0 1"/>
  </joint>

  <joint name="swerve_left_front_joint" type="continuous">
    <parent link="base_link"/>
    <child link="swerve_left_front_link"/>
    <origin rpy="0 0 0" xyz="0.25 0.25 0.1"/>
    <axis xyz="0 0 1"/>
  </joint>

  <joint name="swerve_right_front_joint" type="continuous">
    <parent link="base_link"/>
    <child link="swerve_right_front_link"/>
    <origin rpy="0 0 0" xyz="0.25 -0.25 0.1"/>
    <axis xyz="0 0 1"/>
  </joint>

  <joint name="swerve_left_back_joint" type="continuous">
    <parent link="base_link"/>
    <child link="swerve_left_back_link"/>
    <origin rpy="0 0 0" xyz="-0.25 0.25 0.1"/>
    <axis xyz="0 0 1"/>
  </joint>

  <joint name="swerve_right_back_joint" type="continuous">
    <parent link="base_link"/>
    <child link="swerve_right_back_link"/>
    <origin rpy="0 0 0" xyz="-0.25 -0.25 0.1"/>
    <axis xyz="0 0 1"/>
  </joint>

  <joint name="left_front_joint" type="continuous">
    <parent link="swerve_left_front_link"/>
    <child link="left_front_wheel"/>
    <origin rpy="-1.5712963 0 0" xyz="0 0 0"/>    
    <axis xyz="0 0 1"/>
  </joint>

  <joint name="right_front_joint" type="continuous">
    <parent link="swerve_right_front_link"/>
    <child link="right_front_wheel"/>
    <origin rpy="-1.5712963 0 0" xyz="0 0 0"/>
    <axis xyz="0 0 1"/>
  </joint>

  <joint name="left_back_joint" type="continuous">
    <parent link="swerve_left_back_link"/>
    <child link="left_back_wheel"/>
    <origin rpy="-1.5712963 0 0" xyz="0 0 0"/>
    <axis xyz="0 0 1"/>
  </joint>

  <joint name="right_back_joint" type="continuous">
    <parent link="swerve_right_back_link"/>
    <child link="right_back_wheel"/>
    <origin rpy="-1.5712963 0 0" xyz="0 0 0"/>
    <axis xyz="0 0 1"/>
  </joint>

  <transmission name="left_front_wheel_trans">
    <type>transmission_interface/SimpleTransmission</type>
    <joint name="left_front_joint"/>
    <actuator name="left_front_motor">
      <hardwareInterface>hardware_interface/VelocityJointInterface</hardwareInterface>
      <mechanicalReduction>1</mechanicalReduction>
    </actuator>
  </transmission>

  <transmission name="right_front_wheel_trans">
    <type>transmission_interface/SimpleTransmission</type>
    <joint name="right_front_joint"/>
    <actuator name="right_front_motor">
      <hardwareInterface>hardware_interface/VelocityJointInterface</hardwareInterface>
      <mechanicalReduction>1</mechanicalReduction>
    </actuator>
  </transmission>

  <transmission name="left_back_wheel_trans">
    <type>transmission_interface/SimpleTransmission</type>
    <joint name="left_back_joint"/>
    <actuator name="left_back_motor">
      <hardwareInterface>hardware_interface/VelocityJointInterface</hardwareInterface>
      <mechanicalReduction>1</mechanicalReduction>
    </actuator>
  </transmission>

  <transmission name="right_back_wheel_trans">
    <type>transmission_interface/SimpleTransmission</type>
    <joint name="right_back_joint"/>
    <actuator name="right_back_motor">
      <hardwareInterface>hardware_interface/VelocityJointInterface</hardwareInterface>
      <mechanicalReduction>1</mechanicalReduction>
    </actuator>
  </transmission>  

</robot>
